Workbook

Sheet 入居者管理表
A1: 部屋番号 | B1: 名前 | C1: 入居日 | D1: 介護度 | E1: 誕生日 | F1: 年齢 | G1: 訪問医 | H1: 口腔衛生 | I1: 福祉用具 | J1: ごはん | K1: おかず | L1: とろみ | M1: エアコン | N1: 早出し | P1: 費用目安
A2: 201 | B2: 熊木 勝 | C2: 46217 | D2: 4 | E2: S24/06/08 | F2: 77 | G2: 井上Dr. 城西 | I2: 施 車椅子 | M2: 〇 | P2: 月額実費 | Q2: 家賃 | R2: 管理費 | S2: 食費 | U2: 日割り
A3: 202 | B3: 石垣 和子 | C3: 45846 | D3: 4 | E3: S07/1/12 | F3: 93 | G3: 堀池Dr. とやま | J3: 軟飯 | K3: 一口 | L3: 無し | M3: 〇 | P3: =SUM(Q3:S3) -> 210640 | Q3: 58000 | R3: 91080 | S3: 61560 | T3: =SUM(Q3:S3) -> 210640 | U3: =P3/30 -> 7021.3333
A4: 203 | B4: 長谷川 明代 | C4: 45351 | D4: 4 | E4: S13/9/29 | F4: 87 | G4: 堀池Dr. とやま | H4: 小嶋デンタル | I4: 施 車椅子 | J4: 軟飯 | K4: 普通 | M4: 〇 | N4: 早出し
A5: 204 | B5: 瀬川 清江 | C5: 46042 | D5: 4 | E5: S07/09/06 | F5: 94 | G5: 井上Dr. 城西 | I5: レ リクライニング式車椅子 | J5: 全粥 | K5: きざみ | L5: あり | M5: 〇 | P5: 食事なし実費
A6: 205 | B6: 南 君江 | C6: 43770 | D6: 1 | E6: S1/12/25 | F6: 99 | G6: 野村Dr. 静岡ホーム | H6: 小嶋デンタル | I6: 購 歩行器 | J6: 軟飯 | K6: 普通 | L6: 無し | M6: × | P6: =SUM(Q6:S6) -> 149080 | Q6: 58000 | R6: 91080 | S6: 0 | U6: =P6/30 -> 4969.3333
A7: 206 | B7: 内山 和司 | C7: 46057 | D7: 1 | E7: S09/03/01 | F7: 92 | G7: 日野Dr. 城西 | I7: 施 車椅子 | J7: パン | K7: 一口 | L7: 無し | M7: 〇
A8: 207 | B8: 佐野 益浩 | C8: 45112 | D8: 1 | E8: S15/02/01 | F8: 85 | G8: 日野Dr. 城西 | I8: 施 車椅子 | J8: 米飯 | K8: 普通 | L8: 無し | M8: × | P8: 介護1 | Q8: 介護2 | R8: 介護3 | S8: 介護4 | T8: 介護5
A9: 208 | B9: 堀池 智恵子 | C9: 44918 | D9: 2 | E9: S5/09/05 | F9: 95 | G9: 井上Dr. 城西 | H9: さくらばし歯科 | I9: 購 歩行器 | J9: 軟飯 | K9: 普通 | L9: 無し | M9: 〇 | P9: 16699 | Q9: 18764 | R9: 20920 | S9: 22923 | T9: 25049
A10: 209 | B10: 梅原 とし子 | C10: 45056 | D10: 3 | E10: S9/11/03 | F10: 91 | G10: 堀池Dr. とやま | H10: さくらばし歯科 | I10: 購 歩行器, 施 車椅子 | J10: 軟飯 | K10: 普通 | L10: 無し | M10: × | P10: =P9+P3 -> 227339 | Q10: =Q9+P3 -> 229404 | R10: =R9+P3 -> 231560 | S10: =S9+P3 -> 233563 | T10: =P3+T9 -> 235689
A11: 210 | B11: 鈴木 トヨ江 | C11: 44998 | D11: 4 | E11: S8/12/13 | F11: 93 | G11: 日野Dr. 城西 | I11: レ リクライニング式車椅子 | J11: 全粥 | K11: きざみ | L11: 無し | M11: 〇 | P11: =P9*2 -> 33398 | Q11: =Q9*2 -> 37528 | R11: =R9*2 -> 41840 | S11: =S9*2 -> 45846 | T11: =T9*2 -> 50098
A12: 211 | B12: 飯塚 愛子 | C12: 45632 | D12: 2 | E12: S16/01/01 | F12: 84 | G12: 内田Dr. 静岡ホーム | I12: 施 車椅子 | J12: 軟飯 | K12: 一口 | L12: 無し | M12: 〇 | P12: =P11+P3 -> 244038 | Q12: =Q11+P3 -> 248168 | R12: =R11+P3 -> 252480 | S12: =S11+P3 -> 256486 | T12: =P3+T11 -> 260738
A13: 212 | B13: 吉崎 壽江 | C13: 45548 | D13: 5 | E13: S9/08/21 | F13: 91 | G13: 日野Dr. 城西 | H13: 小嶋デンタル | I13: 施 車椅子 | J13: 米飯 | K13: 普通 | L13: 無し | M13: 〇 | N13: 早出し | P13: =P9*3 -> 50097 | Q13: =Q9*3 -> 56292 | R13: =R9*3 -> 62760 | S13: =S9*3 -> 68769 | T13: =T9*3 -> 75147
A14: 213 | B14: 西澤 惠美子 | C14: 45720 | D14: 2 | E14: S11/9/06 | F14: 89 | G14: 平野Dr 平野 | H14: さくらばし歯科 | I14: 施 歩行器 | J14: 米飯 | K14: 普通 | M14: 〇 | P14: =P13+P3 -> 260737 | Q14: =Q13+P3 -> 266932 | R14: =R13+P3 -> 273400 | S14: =S13+P3 -> 279409 | T14: =T13+P3 -> 285787
A15: 214 | B15: 大長 まさ | C15: 44278 | D15: 2 | E15: T11/04/20 | F15: 103 | G15: 日野Dr. 城西 | H15: 小嶋デンタル | I15: 購 歩行器 | J15: 軟飯 | K15: きざみ | L15: 無し | M15: 〇
A16: 215 | B16: 堀井 義介 | C16: 45751 | D16: 1 | E16: S07/01/18 | F16: 93 | G16: 堀池Dr. とやま | I16: 施 車椅子 | J16: 軟飯 | K16: 一口 | L16: 無し | M16: 〇
A17: 216 | B17: 竹田 朝枝 | C17: 44917 | D17: 5 | E17: S9/01/30 | F17: 92 | G17: 日野Dr. 城西 | H17: さくらばし歯科 | I17: レ リクライニング式車椅子 | J17: 全粥 | K17: きざみ | M17: × | N17: 早出し
A18: 217 | B18: 海老原 暁子 | C18: 45898 | D18: 2 | E18: S16/12/16 | F18: 84 | G18: 堀池Dr. とやま | J18: 米飯 | K18: 普通 | M18: 〇
A19: 218 | B19: 堀井 千沙 | C19: 46155 | D19: 1 | E19: S15/10/02 | F19: 86 | G19: 堀池Dr. とやま | J19: 全粥
A20: 219 | B20: 山田 はる江 | C20: 44009 | D20: 3 | E20: S2/02/15 | F20: 98 | G20: 堀池Dr. とやま | H20: 小嶋デンタル | I20: レ 車椅子 | J20: 全粥 | K20: きざみ | M20: ×
A21: 220 | B21: 西澤 惠美子 | C21: 45720 | D21: 2 | E21: S11/9/06 | F21: 89 | G21: 平野Dr 平野 | H21: さくらばし歯科 | I21: 施 歩行器 | J21: 米飯 | K21: 普通 | M21: 〇
A22: 221 | B22: 澤田 和男 | C22: 45873 | D22: 2 | E22: S10/10/06 | F22: 89 | G22: 平野Dr 平野 | I22: レ 車椅子 | J22: 米飯 | K22: 普通 | M22: 〇
A23: 222 | B23: 花村 喜平 | C23: 46213 | D23: 1 | E23: S14/08/08 | F23: 87 | G23: 井上Dr. 城西 | J23: 米飯 | K23: 普通 | M23: ×
A24: 223 | B24: 八倉 昌弘 | C24: 44972 | D24: 3 | E24: S13/10/1 | F24: 87 | G24: 堀池Dr. とやま | H24: さくらばし歯科 | I24: 施 車椅子 | J24: 全粥 | K24: 極キザミ | M24: ×
A25: 224 | B25: 小田 芳江 | C25: 45813 | D25: 3 | E25: S11/10/21 | F25: 89 | G25: 堀池Dr. とやま | H25: さくらばし歯科 | I25: レ 歩行器 | J25: 米飯 | K25: 普通 | M25: 〇
A26: 225 | B26: 松浦 睦子 | C26: 43347 | D26: 4 | E26: S13/1/10 | F26: 88 | G26: 平野Dr 平野 | H26: 小嶋デンタル | I26: 購 歩行器 | J26: 軟飯 | K26: 普通 | L26: 無し | M26: 〇
A27: 301 | B27: 一杉 洋子 | C27: 45826 | D27: 2 | E27: S24/05/08 | F27: 76 | G27: 日野Dr. 城西 | I27: 購 歩行器 | J27: 米飯 | K27: 普通 | M27: 〇
A28: 302 | B28: 田中 晨子 | C28: 43002 | D28: 3 | E28: S13/03/5 | F28: 87 | G28: 梅内Dr. 静岡ホーム | H28: 小嶋デンタル | I28: 購 歩行器 | J28: 米飯 | K28: 普通 | M28: 〇
A29: 303 | B29: 狩野 厚子 | C29: 45909 | D29: 2 | E29: S28/7/19 | F29: 72 | G29: 堀池Dr. とやま | I29: レ 車椅子 | J29: 米飯 | K29: 普通 | M29: 〇
A30: 304 | B30: 藁科 玉江 | C30: 45723 | D30: 3 | E30: S16/08/18 | F30: 84 | G30: 日野Dr. 城西 | I30: レ 車椅子 | J30: ミキサー | K30: ミキサー | M30: 〇
A31: 305 | B31: 志田美智子 | C31: 45104 | D31: 2 | E31: S8/04/02 | F31: 92 | G31: 井上Dr. 城西 | I31: 施 車椅子 | J31: 全粥 | K31: 一口 | M31: ×
A32: 306 | B32: 小澤 増江 | C32: 46098 | D32: 2 | E32: S20/03/05 | F32: 81 | G32: 堀池Dr. とやま | I32: レ 車椅子 | J32: 軟飯 | K32: 一口 | M32: 〇
A33: 307 | B33: 漆畑 彌千代 | C33: 44232 | D33: 1 | E33: S14/8/08 | F33: 86 | G33: 堀池Dr. とやま | H33: 小嶋デンタル | J33: 米飯 | K33: 普通 | M33: 〇
A34: 308 | B34: 鈴木 登喜江 | C34: 45644 | D34: 5 | E34: T15/5/12 | F34: 99 | G34: 堀池Dr. とやま | I34: 施 車椅子, 施 歩行器 | J34: 全粥 | K34: 一口 | M34: 〇
A35: 309 | B35: 稲葉 恵美子 | C35: 45729 | D35: 2 | E35: S09/11/27 | F35: 91 | G35: 平野Dr 平野 | J35: 米飯 | K35: 普通 | M35: 〇
A36: 310 | B36: 安田 愛子 | C36: 45754 | D36: 1 | E36: S02/04/03 | F36: 98 | G36: 野村Dr. 静岡ホーム | H36: 小嶋デンタル | I36: 施 車椅子 | J36: 全粥 | K36: 極キザミ | M36: 〇
A37: 311 | B37: 池田 久雄 | C37: 45338 | D37: 2 | E37: S7/08/02 | F37: 93 | G37: 日野Dr. 城西 | H37: さくらばし歯科 | I37: 歩行器 | J37: 軟飯 | K37: 一口 | M37: ×
A38: 312 | B38: 石川 トメ子 | C38: 45962 | D38: 3 | E38: S06/11/01 | F38: 94 | G38: 堀池Dr. とやま | I38: レ 車椅子 | J38: 軟飯 | K38: 一口 | M38: 〇
A39: 313 | B39: 片平 美津江 | C39: 45888 | D39: 4 | E39: S11/11/10 | F39: 89 | G39: 井上Dr. 城西 | I39: 施 車椅子 | J39: 軟飯 | K39: 一口 | M39: 〇
A40: 314 | B40: 三浦 一枝 | C40: 45194 | D40: 2 | E40: S8/01/30 | F40: 93 | G40: 井上Dr. 城西 | H40: 小嶋デンタル | J40: 軟飯 | K40: 一口 | M40: 〇
...

Sheet シート8
A1: 部屋番号 | B1: 名前 | C1: 入居日 | D1: 介護度 | E1: 誕生日 | F1: 年齢
A2: 201 | B2: 熊木 勝 | C2: 46217 | D2: 4 | E2: S24/06/08 | F2: 77
A3: 202 | B3: 石垣 和子 | C3: 45846 | D3: 4 | E3: S07/1/12 | F3: 93
A4: 203 | B4: 長谷川 明代 | C4: 45351 | D4: 4 | E4: S13/9/29 | F4: 87
A5: 204 | B5: 瀬川 清江 | C5: 46042 | D5: 4 | E5: S07/09/06 | F5: 94
A6: 205 | B6: 南 君江 | C6: 43770 | D6: 1 | E6: S1/12/25 | F6: 99
A7: 206 | B7: 内山 和司 | C7: 46057 | D7: 1 | E7: S09/03/01 | F7: 92
A8: 207 | B8: 佐野 益浩 | C8: 45112 | D8: 1 | E8: S15/02/01 | F8: 85
A9: 208 | B9: 堀池 智恵子 | C9: 44918 | D9: 2 | E9: S5/09/05 | F9: 95
A10: 209 | B10: 梅原 とし子 | C10: 45056 | D10: 3 | E10: S9/11/03 | F10: 91
A11: 210 | B11: 鈴木 トヨ江 | C11: 44998 | D11: 4 | E11: S8/12/13 | F11: 93
A12: 211 | B12: 飯塚 愛子 | C12: 45632 | D12: 2 | E12: S16/01/01 | F12: 84
A13: 212 | B13: 吉崎 壽江 | C13: 45548 | D13: 5 | E13: S9/08/21 | F13: 91
... A46: 320 | B46: 小倉 馨 | C46: 45547 | D46: 3 | E46: S7/02/18 | F46: 93
A47: 321
A48: 322 | B48: 青嶋 アツ子 | C48: 45621 | D48: 2 | E48: S15/11/01 | F48: 85
A49: 323 | B49: 佐藤 みつ子 | C49: 43436 | D49: 5 | E49: S5/10/04 | F49: 96
A50: 324 | B50: 野田 久子 | C50: 45413 | D50: 2 | E50: S15/7/07 | F50: 85
A51: 325 | B51: 石部 きみ子 | C51: 45992 | D51: 2 | E51: S08/02/10 | F51: 92

Sheet シート6
I1: おむつ・パッド類集計表 （よみよみ） | R1: 令和8年 | T1: 3月分
C2: お客様名 | E2: 尿取りパッド スーパー | G2: うす型快適 パンツ | H2: うす型快適 パンツ | I2: 一晩中安心 さらさらパッド | J2: 長時間安心 さらさら パッド | K2: かんたん装着 パッド | L2: かんたん装着 パッド | N2: 快適さらさら カバータイプ | P2: 快適さらさら カバータイプ | R2: さわやかパッド 快適の中量用 | S2: さわやかパッド 安心の中菱用 | T2: 合計 | U2: おしり ふき | W2: 合計額 | X2: 合計額
E3: 男女共用 | G3: レギュラー M28 | H3: レギュラー L26 | I3: スーパー45 | J3: 48枚 | K3: レギュラー54 | L3: スーパー 28枚 | N3: S-M | P3: L | R3: 50cc | S3: 100cc
A4: 1 | B4: 201 | C4: 小澤 よし子 | D4: 様 | E4: 2 | J4: 1 | T4: 0 | W4: 0 | X4: 0
A5: 2 | B5: 202 | C5: 石垣 和子 | D5: 様 | G5: 1 | T5: 0 | W5: 0 | X5: 0
A6: 3 | B6: 203 | C6: 長谷川 明代 | D6: 様 | E6: 3 | I6: 1 | T6: 0 | W6: 0 | X6: 0
A7: 4 | B7: 204 | C7: 瀬川 清江 | D7: 様 | J7: 1 | T7: 0 | W7: 0 | X7: 0
A8: 5 | B8: 205 | C8: 南 君江 | D8: 様 | T8: 0 | W8: 0 | X8: 0
A9: 6 | B9: 206 | C9: 内山 和司 | D9: 様 | G9: 1 | T9: 0 | W9: 0 | X9: 0
A10: 7 | B10: 207 | C10: 佐野 益浩 | D10: 様 | T10: 0 | W10: 0 | X10: 0
A11: 8 | B11: 208 | C11: 堀池 智惠子 | D11: 様 | J11: 2 | T11: 0 | W11: 0 | X11: 0
A12: 9 | B12: 209 | C12: 梅原 とし子 | D12: 様 | J12: 1 | K12: 1 | T12: 0 | W12: 0 | X12: 0
A13: 10 | B13: 210 | C13: 鈴木 トヨ江 | D13: 様 | I13: 2 | J13: 1 | T13: 0 | W13: 0 | X13: 0
A14: 11 | B14: 211 | C14: 飯塚 愛子 | D14: 様 | E14: 2 | I14: 1 | T14: 350 | W14: 0 | X14: 0
A15: 12 | B15: 212 | C15: 吉﨑 壽江 | D15: 様 | T15: 0 | W15: 0 | X15: 0
A16: 13 | B16: 213 | C16: 仲田 幸子 | D16: 様 | G16: 1 | T16: 0 | W16: 0 | X16: 0
A17: 14 | B17: 214 | C17: 大長 まさ | D17: 様 | T17: 0 | W17: 0 | X17: 0
A18: 15 | B18: 215 | C18: 堀井 義介 | D18: 様 | G18: 1 | K18: 1 | T18: 0 | W18: 0 | X18: 0
A19: 16 | B19: 216 | C19: 竹田 朝枝 | D19: 様 | T19: 0 | W19: 0 | X19: 0
A20: 17 | B20: 217 | C20: 海老原 暁子 | D20: 様 | G20: 3 | K20: 1 | T20: 0 | W20: 0 | X20: 0
A21: 18 | B21: 218 | C21: 望月 清子 | D21: 様 | E21: 2 | T21: 0 | W21: 0 | X21: 0
A22: 19 | B22: 219 | C22: 山田 はる江 | D22: 様 | I22: 2 | K22: 1 | L22: 1 | T22: 0 | W22: 0 | X22: 0
A23: 20 | B23: 220 | C23: 西澤 恵美子 | D23: 様 | T23: 0 | W23: 0 | X23: 0
A24: 21 | B24: 221 | C24: 澤田 和男 | D24: 様 | G24: 1 | K24: 3 | T24: 0 | W24: 0 | X24: 0
A25: 22 | B25: 222 | C25: 山本 君江 | D25: 様 | E25: 1 | G25: 1 | J25: 1 | T25: 0 | W25: 0 | X25: 0
A26: 23 | B26: 223 | C26: 八倉 昌弘 | D26: 様 | L26: 1 | T26: 0 | W26: 0 | X26: 0
A27: 24 | B27: 224 | C27: 小田 芳江 | D27: 様 | T27: 0 | W27: 0 | X27: 0
A28: 25 | B28: 225 | C28: 松浦 睦子 | D28: 様 | I28: 2 | K28: 2 | T28: 0 | W28: 0 | X28: 0
A29: 26 | B29: 301 | C29: 一杉 洋子 | D29: 様 | G29: 5 | T29: 0 | W29: 0 | X29: 0
A30: 27 | B30: 302 | C30: 田中 晨子 | D30: 様 | E30: 2 | J30: 1 | T30: 0 | W30: 0 | X30: 0
A31: 28 | B31: 303 | C31: 狩野 厚子 | D31: 様 | H31: 1 | J31: 2 | K31: 1 | T31: 0 | W31: 0 | X31: 0
A32: 29 | B32: 304 | C32: 藁科 玉江 | D32: 様 | E32: 2 | J32: 2 | T32: 0 | W32: 0 | X32: 0
A33: 30 | B33: 305 | C33: 志田 美智子 | D33: 様 | T33: 0 | W33: 0 | X33: 0
A34: 31 | B34: 306 | C34: 小澤 増江 | D34: 様 | T34: 0 | W34: 0 | X34: 0
A35: 32 | B35: 306 | C35: 片又 勝美 | D35: 様 | T35: 0 | W35: 0 | X35: 0
A36: 33 | B36: 307 | C36: 漆畑 彌千代 | D36: 様 | T36: 0 | W36: 0 | X36: 0
A37: 34 | B37: 308 | C37: 鈴木 登喜江 | D37: 様 | E37: 2 | G37: 1 | T37: 0 | W37: 0 | X37: 0
A38: 35 | B38: 309 | C38: 稲葉 恵美子 | D38: 様 | T38: 0 | W38: 0 | X38: 0
A39: 36 | B39: 310 | C39: 安田 愛子 | D39: 様 | T39: 0 | W39: 0 | X39: 0
A40: 37 | B40: 311 | C40: 池田 久雄 | D40: 様 | G40: 1 | K40: 1 | T40: 0 | W40: 0 | X40: 0
...

Sheet シート7
A1: 201 | B1: 小澤 よし子 | C1: 様 | D1: 2 | I1: 1 | S1: 0 | V1: 0 | W1: 0
A2: 202 | B2: 石垣 和子 | C2: 様 | F2: 1 | S2: 0 | V2: 0 | W2: 0
A3: 203 | B3: 長谷川 明代 | C3: 様 | D3: 3 | H3: 1 | S3: 0 | V3: 0 | W3: 0
A4: 204 | B4: 瀬川 清江 | C4: 様 | I4: 1 | S4: 0 | V4: 0 | W4: 0
A5: 205 | B5: 南 君江 | C5: 様 | S5: 0 | V5: 0 | W5: 0
A6: 206 | B6: 内山 和司 | C6: 様 | F6: 1 | S6: 0 | V6: 0 | W6: 0
A7: 207 | B7: 佐野 益浩 | C7: 様 | S7: 0 | V7: 0 | W7: 0
A8: 208 | B8: 堀池 智惠子 | C8: 様 | I8: 2 | S8: 0 | V8: 0 | W8: 0
A9: 209 | B9: 梅原 とし子 | C9: 様 | I9: 1 | J9: 1 | S9: 0 | V9: 0 | W9: 0
A10: 210 | B10: 鈴木 トヨ江 | C10: 様 | H10: 2 | I10: 1 | S10: 0 | V10: 0 | W10: 0
A11: 211 | B11: 飯塚 愛子 | C11: 様 | D11: 2 | H11: 1 | S11: 350 | V11: 0 | W11: 0
A12: 212 | B12: 吉﨑 壽江 | C12: 様 | S12: 0 | V12: 0 | W12: 0
A13: 213 | B13: 仲田 幸子 | C13: 様 | F13: 1 | S13: 0 | V13: 0 | W13: 0
A14: 214 | B14: 大長 まさ | C14: 様 | S14: 0 | V14: 0 | W14: 0
A15: 215 | B15: 堀井 義介 | C15: 様 | F15: 1 | J15: 1 | S15: 0 | V15: 0 | W15: 0
A16: 216 | B16: 竹田 朝枝 | C16: 様 | S16: 0 | V16: 0 | W16: 0
A17: 217 | B17: 海老原 暁子 | C17: 様 | F17: 3 | J17: 1 | S17: 0 | V17: 0 | W17: 0
A18: 218 | B18: 望月 清子 | C18: 様 | D18: 2 | S18: 0 | V18: 0 | W18: 0
A19: 219 | B19: 山田 はる江 | C19: 様 | H19: 2 | J19: 1 | K19: 1 | S19: 0 | V19: 0 | W19: 0
A20: 220 | B20: 西澤 恵美子 | C20: 様 | S20: 0 | V20: 0 | W20: 0
A21: 221 | B21: 澤田 和男 | C21: 様 | F21: 1 | J21: 3 | S21: 0 | V21: 0 | W21: 0
A22: 222 | B22: 山本 君江 | C22: 様 | D22: 1 | F22: 1 | I22: 1 | S22: 0 | V22: 0 | W22: 0
A23: 223 | B23: 八倉 昌弘 | C23: 様 | K23: 1 | S23: 0 | V23: 0 | W23: 0
A24: 224 | B24: 小田 芳江 | C24: 様 | S24: 0 | V24: 0 | W24: 0
A25: 225 | B25: 松浦 睦子 | C25: 様 | H25: 2 | J25: 2 | S25: 0 | V25: 0 | W25: 0
A26: 301 | B26: 一杉 洋子 | C26: 様 | F26: 5 | S26: 0 | V26: 0 | W26: 0
A27: 302 | B27: 田中 晨子 | C27: 様 | D27: 2 | I27: 1 | S27: 0 | V27: 0 | W27: 0
A28: 303 | B28: 狩野 厚子 | C28: 様 | G28: 1 | I28: 2 | J28: 1 | S28: 0 | V28: 0 | W28: 0
A29: 304 | B29: 藁科 玉江 | C29: 様 | D29: 2 | I29: 2 | S29: 0 | V29: 0 | W29: 0
A30: 305 | B30: 志田 美智子 | C30: 様 | S30: 0 | V30: 0 | W30: 0
A31: 306 | B31: 小澤 増江 | C31: 様 | S31: 0 | V31: 0 | W31: 0
A32: 306 | B32: 片又 勝美 | C32: 様 | S32: 0 | V32: 0 | W32: 0
A33: 307 | B33: 漆畑 彌千代 | C33: 様 | S33: 0 | V33: 0 | W33: 0
A34: 308 | B34: 鈴木 登喜江 | C34: 様 | D34: 2 | F34: 1 | S34: 0 | V34: 0 | W34: 0
A35: 309 | B35: 稲葉 恵美子 | C35: 様 | S35: 0 | V35: 0 | W35: 0
A36: 310 | B36: 安田 愛子 | C36: 様 | S36: 0 | V36: 0 | W36: 0
A37: 311 | B37: 池田 久雄 | C37: 様 | F37: 1 | J37: 1 | S37: 0 | V37: 0 | W37: 0
A38: 312 | B38: 前田 みさ枝 | C38: 様 | D38: 1 | S38: 0 | V38: 0 | W38: 0
A39: 313 | B39: 片平 美津江 | C39: 様 | D39: 2 | F39: 1 | I39: 1 | S39: 0 | V39: 0 | W39: 0
A40: 314 | B40: 三浦 一枝 | C40: 様 | S40: 0 | V40: 0 | W40: 0
...

Sheet シート5
A1: 小澤よし子
A2: 石垣和子
A3: 長谷川明代
A4: 鈴木勝代
A5: 南 君江
A6: 松浦睦子
A7: 佐野益浩
A8: 堀池智恵子
A9: 梅原とし子
A10: 鈴木トヨ江
A11: 飯塚愛子
A12: 吉崎壽江
... A50: 服部やす

Sheet シート2
A1: 207 | C1: 206
A2: ='入居者管理表'!B8 -> 佐野 益浩 | C2: ='入居者管理表'!B7 -> 内山 和司
A3: ='入居者管理表'!D8 -> 1 | C3: ='入居者管理表'!D7 -> 1
A6: 208 | C6: 205
A7: ='入居者管理表'!B9 -> 堀池 智恵子 | C7: ='入居者管理表'!B6 -> 南 君江
A8: ='入居者管理表'!D9 -> 2 | C8: ='入居者管理表'!D6 -> 1
A11: 209 | C11: 204
A12: ='入居者管理表'!B10 -> 梅原 とし子 | C12: ='入居者管理表'!B5 -> 瀬川 清江
A13: ='入居者管理表'!D10 -> 3 | C13: ='入居者管理表'!D5 -> 4
A16: 210 | C16: 203
A17: ='入居者管理表'!B11 -> 鈴木 トヨ江 | C17: ='入居者管理表'!B4 -> 長谷川 明代
A18: ='入居者管理表'!D11 -> 4 | C18: ='入居者管理表'!D4 -> 4
A21: 211 | C21: 202
A22: ='入居者管理表'!B12 -> 飯塚 愛子 | C22: ='入居者管理表'!B101 -> 仲田 幸子
A23: ='入居者管理表'!D12 -> 2 | C23: ='入居者管理表'!D101 -> 1
A26: 212 | C26: 201
A27: ='入居者管理表'!B13 -> 吉崎 壽江 | C27: ='入居者管理表'!B2 -> 熊木 勝
A28: ='入居者管理表'!D13 -> 5 | C28: ='入居者管理表'!D2 -> 4
K29: 225 | L29: 224 | M29: 223
K30: ='入居者管理表'!B26 -> 松浦 睦子 | L30: ='入居者管理表'!B25 -> 小田 芳江 | M30: ='入居者管理表'!B24 -> 八倉 昌弘
K31: ='入居者管理表'!D26 -> 4 | L31: ='入居者管理表'!D25 -> 3 | M31: ='入居者管理表'!D24 -> 3
D36: 213 | E36: 214 | F36: 215 | G36: 216 | H36: 217 | I36: 218 | J36: 219 | K36: 220 | L36: 221 | M36: 222
D37: ='入居者管理表'!B101 -> 仲田 幸子 | E37: ='入居者管理表'!B15 -> 大長 まさ | F37: ='入居者管理表'!B16 -> 堀井 義介 | G37: ='入居者管理表'!B17 -> 竹田 朝枝 | H37: ='入居者管理表'!B18 -> 海老原 暁子 | I37: ='入居者管理表'!B19 -> 堀井 千沙 | J37: ='入居者管理表'!B20 -> 山田 はる江 | K37: ='入居者管理表'!B21 -> 西澤 惠美子 | L37: ='入居者管理表'!B22 -> 澤田 和男 | M37: ='入居者管理表'!B100 -> 山本 君江
D38: ='入居者管理表'!D101 -> 1 | E38: ='入居者管理表'!D15 -> 2 | F38: ='入居者管理表'!D16 -> 1 | G38: ='入居者管理表'!D17 -> 5 | H38: ='入居者管理表'!D18 -> 2 | I38: ='入居者管理表'!D19 -> 1 | J38: ='入居者管理表'!D20 -> 3 | K38: ='入居者管理表'!D21 -> 2 | L38: ='入居者管理表'!D22 -> 2 | M38: ='入居者管理表'!D100 -> 1
A43: 305 | C43: 304
A44: ='入居者管理表'!B31 -> 志田美智子 | C44: ='入居者管理表'!B30 -> 藁科 玉江
A45: ='入居者管理表'!D31 -> 2 | C45: ='入居者管理表'!D30 -> 3
A48: 306 | C48: 303
A49: ='入居者管理表'!B32 -> 小澤 増江 | C49: ='入居者管理表'!B29 -> 狩野 厚子
A50: ='入居者管理表'!D32 -> 2 | C50: ='入居者管理表'!D29 -> 2
A53: 307 | C53: 302
A54: ='入居者管理表'!B33 -> 漆畑 彌千代 | C54: ='入居者管理表'!B28 -> 田中 晨子
A55: ='入居者管理表'!D33 -> 1 | C55: ='入居者管理表'!D28 -> 3
A58: 308 | C58: 301
A59: ='入居者管理表'!B34 -> 鈴木 登喜江 | C59: ='入居者管理表'!B27 -> 一杉 洋子
A60: ='入居者管理表'!D34 -> 5 | C60: ='入居者管理表'!D27 -> 2
A63: 309
A64: ='入居者管理表'!B35 -> 稲葉 恵美子
A65: ='入居者管理表'!D35 -> 2
A68: 310
...

Sheet シート1 のコピー
A1: 部屋番号 | B1: 名前 | C1: 入居日 | D1: 介護度 | E1: 誕生日 | F1: 年齢 | G1: 訪問医 | H1: レンタル | I1: 写真 | J1: Column 10
A2: 201 | B2: 小澤よし子 | C2: 45566 | D2: 3 | E2: T15/3/21 | F2: 99 | G2: 堀池Dr. とやま | H2: 歩行器 | I2: 〇
A3: 202 | B3: 仲田幸子 | C3: 45792 | D3: 1 | E3: S4/03/21 | F3: 96 | G3: 日野Dr. 城西 | I3: 〇
A4: 203 | B4: 長谷川明代 | C4: 45351 | D4: 4 | E4: S13/9/29 | F4: 87 | G4: 堀池Dr. とやま | I4: 〇
A5: 204 | B5: 鈴木勝代 | C5: 43474 | D5: 4 | E5: S17/2/20 | F5: 83 | G5: 堀池Dr. とやま | H5: 多機能車椅子 | I5: 〇
A6: 205 | B6: 南 君江 | C6: 43770 | D6: 1 | E6: S1/12/25 | F6: 99 | G6: 野村Dr. 静岡ホーム | I6: 〇
A7: 206 | B7: 松浦睦子 | C7: 43347 | D7: 3 | E7: S13/1/10 | F7: 88 | G7: 平野Dr 平野 | I7: 〇
A8: 207 | B8: 佐野益浩 | C8: 45112 | D8: 1 | E8: S15/02/01 | F8: 85 | G8: 日野Dr. 城西 | I8: 〇
A9: 208 | B9: 堀池智恵子 | C9: 44918 | D9: 2 | E9: S5/09/05 | F9: 95 | G9: 井上Dr. 城西 | I9: 〇
A10: 209 | B10: 梅原とし子 | C10: 45056 | D10: 3 | E10: S9/11/03 | F10: 91 | G10: 堀池Dr. とやま | I10: ×
A11: 210 | B11: 鈴木トヨ江 | C11: 44998 | D11: 4 | E11: S8/12/13 | F11: 92 | G11: 日野Dr. 城西 | H11: リクライニング式車椅子 | I11: 〇
A12: 211 | B12: 飯塚愛子 | C12: 45632 | D12: 2 | E12: S16/01/01 | F12: 84 | G12: 内田Dr. 静岡ホーム | I12: 〇
A13: 212 | B13: 吉崎壽江 | C13: 45548 | D13: 3 | E13: S9/08/21 | F13: 91 | G13: 日野Dr. 城西 | I13: ×
A14: 213
A15: 214 | B15: 大長まさ | C15: 44278 | D15: 2 | E15: T11/04/20 | F15: 103 | G15: 日野Dr. 城西 | I15: 〇
A16: 215 | B16: 堀井義介 | C16: 45751 | D16: 1 | E16: S07/01/18 | F16: 93 | G16: 堀池Dr. とやま | I16: 〇
A17: 216 | B17: 竹田朝枝 | C17: 44917 | D17: 5 | E17: S9/01/30 | F17: 92 | G17: 日野Dr. 城西 | H17: リクライニング式車椅子 | I17: 〇
A18: 217 | B18: 深澤紀久子 | C18: 45827 | D18: 2 | E18: S14/02/11 | F18: 86 | G18: 堀池Dr. とやま | I18: 〇
A19: 218 | B19: 望月清子 | C19: 45414 | D19: 4 | E19: S20/06/25 | F19: 80 | G19: 日野Dr. 城西 | I19: ×
A20: 219 | B20: 山田はる江 | C20: 44009 | D20: 4 | E20: S2/02/15 | F20: 98 | G20: 堀池Dr. とやま | I20: 〇
A21: 220 | B21: 西澤惠美子 | C21: 45720 | D21: 2 | E21: S11/9/06 | F21: 89 | G21: 平野Dr 平野 | H21: 歩行器 | I21: 〇
A22: 221 | E22: 要介護１：１３ | F22: 要介護３：９
A23: 222 | B23: 山本君江 | C23: 45373 | D23: 1 | E23: S7/05/11 | F23: 93 | G23: 堀池Dr. とやま | I23: 〇
A24: 223 | B24: 八倉昌弘 | C24: 44972 | D24: 3 | E24: S13/10/1 | F24: 87 | G24: 堀池Dr. とやま | I24: 〇
A25: 224 | B25: 小田芳江 | C25: 45813 | D25: 2 | E25: S11/10/21 | F25: 89 | G25: 堀池Dr. とやま | I25: 〇
A26: 225 | B26: 高橋和代 | C26: 44580 | D26: 4 | E26: S2/02/16 | F26: 98 | G26: 東静岡 | H26: 多機能車椅子 | I26: 〇
A27: 301 | B27: 一杉洋子 | C27: 45826 | D27: 1 | E27: S24/05/08 | F27: 76 | G27: 日野Dr. 城西 | I27: 〇
A28: 302 | B28: 田中晨子 | C28: 43002 | D28: 3 | E28: S13/03/5 | F28: 87 | G28: 梅内Dr. 静岡ホーム | I28: 〇
A29: 303 | B29: 沼本英雄 | C29: 45665 | D29: 3 | E29: S11/8/15 | F29: 89 | G29: 堀池Dr. とやま | I29: 〇
A30: 304 | B30: 藁科玉江 | C30: 45723 | D30: 2 | E30: S16/08/18 | F30: 84 | G30: 日野Dr. 城西 | H30: 多機能車椅子 | I30: 〇
A31: 305 | B31: 志田美智子 | C31: 45104 | D31: 2 | E31: S8/04/02 | F31: 92 | G31: 井上Dr. 城西 | I31: 〇
A32: 306 | B32: 片又勝美 | C32: 45617 | D32: 3 | E32: S11/12/06 | F32: 89 | G32: 堀池Dr. とやま | H32: 多機能車椅子 | I32: 〇
A33: 307 | B33: 漆畑彌千代 | C33: 44232 | D33: 1 | E33: S14/8/08 | F33: 86 | G33: 堀池Dr. とやま | I33: 〇
A34: 308 | B34: 鈴木登喜江 | C34: 45644 | D34: 1 | E34: T15/5/12 | F34: 99 | G34: 堀池Dr. とやま | H34: 手すり | I34: 〇
A35: 309 | B35: 稲葉恵美子 | C35: 45729 | D35: 2 | E35: S09/11/27 | F35: 91 | G35: 平野Dr 平野 | I35: 〇
A36: 310 | B36: 安田愛子 | C36: 45754 | D36: 2 | E36: S02/04/03 | F36: 98 | G36: 野村Dr. 静岡ホーム | I36: 〇
A37: 311 | B37: 池田久雄 | C37: 45338 | D37: 1 | E37: S7/08/02 | F37: 93 | G37: 日野Dr. 城西 | H37: 歩行器 | I37: 〇
A38: 312 | B38: 前田みさ枝 | C38: 45758 | D38: 1 | E38: S04/03/22 | F38: 96 | G38: 梅内Dr. 静岡ホーム | I38: 〇
A39: 313 | E39: 要介護２：１５ | F39: 要介護４：８
A40: 314 | B40: 三浦一枝 | C40: 45194 | D40: 2 | E40: S8/01/30 | F40: 93 | G40: 井上Dr. 城西 | I40: 〇
...

Sheet シート3
A1: 小澤よし子 | B1: 201
A2: 石垣和子 | B2: 202
A3: 長谷川明代 | B3: 203
A4: 鈴木勝代 | B4: 204
A5: 南 君江 | B5: 205
A6: 松浦睦子 | B6: 206
A7: 佐野益浩 | B7: 207
A8: 堀池智恵子 | B8: 208
A9: 梅原とし子 | B9: 209
A10: 鈴木トヨ江 | B10: 210
A11: 飯塚愛子 | B11: 211
A12: 吉崎壽江 | B12: 212
... A50: 服部やす | B50: 325

Sheet 施設備品
B2: ipad | C2: 事務所
C3: ２F-1
C4: ２F-2
C5: ３F-１
C6: ３F-2
B7: デスクトップパソコン | C7: 施設長
C8: 事務員
C9: 相談員
C10: ケアマネ
C11: ３F-1
C12: ３F-2
B13: ノートパソコン | C13: ２F-1
C14: ２F-2
C15: ３F-1
C16: 看護１
C17: 看護２
C18: 機能訓練１
B19: スマートフォン | C19: 施設長
C20: 相談員
C21: 健康管理室１
C22: 健康管理室２
B23: アンドロイドタブレット
